<?xml version="1.0" ?>
<!-- =================================================================================== -->
<!-- |    This document was autogenerated by xacro from panda_arm_hand.urdf.xacro      | -->
<!-- |    EDITING THIS FILE BY HAND IS NOT RECOMMENDED                                 | -->
<!-- =================================================================================== -->
<robot name="panda" xmlns:xacro="http://www.ros.org/wiki/xacro">
  <link name="panda_link0">
    <visual>
      <geometry>
        <mesh filename="meshes/visual/link0.dae"/>
      </geometry>
      <material name="panda_white"/>
    </visual>
    <collision>
      <geometry>
        <mesh filename="meshes/visual/link0.dae"/>
      </geometry>
      <material name="panda_white"/>
    </collision>
    <inertial>
      <origin rpy="0 0 0" xyz="-0.0410181918537986 -0.000143266349590146 0.0499742749991159"/>
      <mass value="0.629769273993887"/>
      <inertia ixx="0.0031531502307724" ixy="8.29043977620386E-07" ixz="0.000153878135879635" iyy="0.00388160500528917" iyz="8.22996985150111E-06" izz="0.00428506837339653"/>
    </inertial>
  </link>
  <link name="panda_link1">
    <visual>
      <geometry>
        <mesh filename="meshes/visual/link1.dae"/>
      </geometry>
      <material name="panda_white"/>
    </visual>
    <collision>
      <geometry>
        <mesh filename="meshes/visual/link1.dae"/>
      </geometry>
      <material name="panda_white"/>
    </collision>
    <inertial>
      <origin rpy="0 0 0" xyz="0.003875 0.002081 -0.04762"/>
      <mass value="4.970684"/>
      <inertia ixx="0.70337" ixy="-0.00013900" ixz="0.0067720" iyy="0.70661" iyz="0.019169" izz="0.0091170"/>
    </inertial>
  </link>
  <joint name="panda_joint1" type="revolute">
    <safety_controller k_position="100.0" k_velocity="40.0" soft_lower_limit="-2.8973" soft_upper_limit="2.8973"/>
    <origin rpy="0 0 0" xyz="0.0005 0.0005 0.3335"/>
    <parent link="panda_link0"/>
    <child link="panda_link1"/>
    <axis xyz="0 0 1"/>
    <limit acceleration="15" effort="87" lower="-2.9671" upper="2.9671" velocity="2.1750"/>
    <dynamics D="1" K="7000" damping="0.003" friction="0.06" mu_coulomb="0" mu_viscous="16"/>
  </joint>
  <link name="panda_link2">
    <visual>
      <geometry>
        <mesh filename="meshes/visual/link2.dae"/>
      </geometry>
      <material name="panda_white"/>
    </visual>
    <collision>
      <geometry>
        <mesh filename="meshes/visual/link2.dae"/>
      </geometry>
      <material name="panda_white"/>
    </collision>
    <inertial>
      <origin rpy="0 0 0" xyz=" -0.003141 -0.02872  0.003495"/>
      <mass value="0.646926"/>
      <inertia ixx="0.0079620" ixy="-3.9250e-3" ixz="1.0254e-02" iyy="2.8110e-02" iyz="7.0400e-04" izz="2.5995e-02"/>
    </inertial>
  </link>
  <joint name="panda_joint2" type="revolute">
    <safety_controller k_position="100.0" k_velocity="40.0" soft_lower_limit="-1.7628" soft_upper_limit="1.7628"/>
    <origin rpy="-1.57079632679 0 0" xyz="0.0005 0.0005 0.0005"/>
    <parent link="panda_link1"/>
    <child link="panda_link2"/>
    <axis xyz="0 0 1"/>
    <limit acceleration="7.5" effort="87" lower="-1.8326" upper="1.8326" velocity="2.1750"/>
    <dynamics D="1" K="7000" damping="0.003" friction="0.06" mu_coulomb="0" mu_viscous="16"/>
  </joint>
  <link name="panda_link3">
    <visual>
      <geometry>
        <mesh filename="meshes/visual/link3.dae"/>
      </geometry>
      <material name="panda_white"/>
    </visual>
    <collision>
      <geometry>
        <mesh filename="meshes/visual/link3.dae"/>
      </geometry>
      <material name="panda_white"/>
    </collision>
    <inertial>
      <origin rpy="0 0 0" xyz="2.75180e-02 3.9252e-02 -6.6502e-02"/>
      <mass value="3.228604"/>
      <inertia ixx="3.7242e-02" ixy="-4.7610e-03" ixz="-1.1396e-02" iyy="3.6155e-02" iyz="-1.2805e-02" izz="1.0830e-02"/>
    </inertial>
  </link>
  <joint name="panda_joint3" type="revolute">
    <safety_controller k_position="100.0" k_velocity="40.0" soft_lower_limit="-2.8973" soft_upper_limit="2.8973"/>
    <origin rpy="1.57079632679 0 0" xyz="0.0005 -0.3155 0.0005"/>
    <parent link="panda_link2"/>
    <child link="panda_link3"/>
    <axis xyz="0 0 1"/>
    <limit acceleration="10" effort="87" lower="-2.9671" upper="2.9671" velocity="2.1750"/>
    <dynamics D="1" K="7000" damping="0.003" friction="0.06" mu_coulomb="0" mu_viscous="16"/>
  </joint>
  <link name="panda_link4">
    <visual>
      <geometry>
        <mesh filename="meshes/visual/link4.dae"/>
      </geometry>
      <material name="panda_white"/>
    </visual>
    <collision>
      <geometry>
        <mesh filename="meshes/visual/link4.dae"/>
      </geometry>
      <material name="panda_white"/>
    </collision>
    <inertial>
      <origin rpy="0 0 0" xyz="-5.317e-02 1.04419e-01 2.7454e-02"/>
      <mass value="3.587895"/>
      <inertia ixx="2.5853e-02" ixy="7.7960e-03" ixz="-1.3320e-03" iyy="1.9552e-02" iyz="8.6410e-03" izz="2.8323e-02"/>
    </inertial>
  </link>
  <joint name="panda_joint4" type="revolute">
    <safety_controller k_position="100.0" k_velocity="40.0" soft_lower_limit="-3.0718" soft_upper_limit="-0.0698"/>
    <origin rpy="1.57079632679 0 0" xyz="0.083 0.0005 0.0005"/>
    <parent link="panda_link3"/>
    <child link="panda_link4"/>
    <axis xyz="0 0 1"/>
    <limit acceleration="12.5" effort="87" lower="-3.1416" upper="0.0" velocity="2.1750"/>
    <dynamics D="1" K="7000" damping="0.003" friction="0.06" mu_coulomb="0" mu_viscous="16"/>
  </joint>
  <link name="panda_link5">
    <visual>
      <geometry>
        <mesh filename="meshes/visual/link5.dae"/>
      </geometry>
      <material name="panda_white"/>
    </visual>
    <collision>
      <geometry>
        <mesh filename="meshes/visual/link5.dae"/>
      </geometry>
      <material name="panda_white"/>
    </collision>
    <inertial>
      <origin rpy="0 0 0" xyz="-1.1953e-02 4.1065e-02 -3.8437e-02"/>
      <mass value="1.225946"/>
      <inertia ixx="3.5549e-02" ixy="-2.1170e-03" ixz="-4.0370e-03" iyy="2.9474e-02" iyz="2.2900e-04" izz="8.6270e-03"/>
    </inertial>
  </link>
  <joint name="panda_joint5" type="revolute">
    <safety_controller k_position="100.0" k_velocity="40.0" soft_lower_limit="-2.8973" soft_upper_limit="2.8973"/>
    <origin rpy="-1.57079632679 0 0" xyz="-0.0820 0.3845 0.0005"/>
    <parent link="panda_link4"/>
    <child link="panda_link5"/>
    <axis xyz="0 0 1"/>
    <limit acceleration="15" effort="12" lower="-2.9671" upper="2.9671" velocity="2.6100"/>
    <dynamics D="1" K="7000" damping="0.003" friction="0.06" mu_coulomb="0" mu_viscous="16"/>
  </joint>
  <link name="panda_link6">
    <visual>
      <geometry>
        <mesh filename="meshes/visual/link6.dae"/>
      </geometry>
      <material name="panda_white"/>
    </visual>
    <collision>
      <geometry>
        <mesh filename="meshes/visual/link6.dae"/>
      </geometry>
      <material name="panda_white"/>
    </collision>
    <inertial>
      <origin rpy="0 0 0" xyz="6.0149e-02 -1.4117e-02 -1.0517e-02"/>
      <mass value="1.666555"/>
      <inertia ixx="1.9640e-03" ixy="1.0900e-04" ixz="-1.1580e-03" iyy="4.3540e-03" iyz="3.4100e-04" izz="5.4330e-03"/>
    </inertial>
  </link>
  <joint name="panda_joint6" type="revolute">
    <safety_controller k_position="100.0" k_velocity="40.0" soft_lower_limit="-0.0175" soft_upper_limit="3.7525"/>
    <origin rpy="1.57079632679 0 0" xyz="0.0005 0.0005 0.0005"/>
    <parent link="panda_link5"/>
    <child link="panda_link6"/>
    <axis xyz="0 0 1"/>
    <limit acceleration="20" effort="12" lower="-0.0873" upper="3.8223" velocity="2.6100"/>
    <dynamics D="1" K="7000" damping="0.003" friction="0.06" mu_coulomb="0" mu_viscous="16"/>
  </joint>
  <link name="panda_link7">
    <visual>
      <geometry>
        <mesh filename="meshes/visual/link7.dae"/>
      </geometry>
      <material name="panda_white"/>
    </visual>
    <collision>
      <geometry>
        <mesh filename="meshes/visual/link7.dae"/>
      </geometry>
      <material name="panda_white"/>
    </collision>
    <inertial>
      <origin rpy="0 0 0" xyz="1.0517e-02 -4.252e-03 6.1597e-02"/>
      <mass value="7.35522e-01"/>
      <inertia ixx="1.2516e-02" ixy="-4.2800e-04" ixz="-1.1960e-03" iyy="1.0027e-02" iyz="-7.4100e-04" izz="4.8150e-03"/>
    </inertial>
  </link>
  <joint name="panda_joint7" type="revolute">
    <safety_controller k_position="100.0" k_velocity="40.0" soft_lower_limit="-2.8973" soft_upper_limit="2.8973"/>
    <origin rpy="1.57079632679 0 0" xyz="0.0885 0.0005 0.0005"/>
    <parent link="panda_link6"/>
    <child link="panda_link7"/>
    <axis xyz="0 0 1"/>
    <limit acceleration="20" effort="12" lower="-2.9671" upper="2.9671" velocity="2.6100"/>
    <dynamics D="1" K="7000" damping="0.003" friction="0.06" mu_coulomb="0" mu_viscous="16"/>
  </joint>
  <joint name="panda_hand_joint" type="fixed">
    <parent link="panda_link7"/>
    <child link="panda_hand"/>
    <origin rpy="0 0 0" xyz="0 0 0.107"/>
  </joint>
  <link name="panda_hand">
    <visual>
      <geometry>
        <mesh filename="meshes/visual/hand.dae"/>
      </geometry>
      <material name="panda_white"/>
    </visual>
    <collision>
      <geometry>
        <mesh filename="meshes/visual/hand.dae"/>
      </geometry>
      <material name="panda_white"/>
    </collision>
    <inertial>
      <mass value="7e-1"/>
      <inertia ixx="5e-3" ixy="0.0" ixz="0.0" iyy="5e-3" iyz="0.0" izz="5e-3"/>
    </inertial>
  </link>
  <link name="panda_leftfinger">
    <visual>
      <origin rpy="0 0 0" xyz="0 0 -0.05"/>
      <geometry>
        <mesh filename="meshes/visual/finger.dae"/>
      </geometry>
      <material name="panda_white"/>
    </visual>
    <collision>
      <geometry>
        <mesh filename="meshes/visual/finger.dae"/>
      </geometry>
      <material name="panda_white"/>
    </collision>
    <inertial>
      <mass value="3e-1"/>
      <inertia ixx="1e-3" ixy="0.0" ixz="0.0" iyy="1e-3" iyz="0.0" izz="1e-3"/>
    </inertial>
  </link>
  <link name="panda_rightfinger">
    <visual>
      <origin rpy="0 0 3.14159265359" xyz="0 0 -0.05"/>
      <geometry>
        <mesh filename="meshes/visual/finger.dae"/>
      </geometry>
      <material name="panda_white"/>
    </visual>
    <collision>
      <origin rpy="0 0 3.14159265359" xyz="0 0 0"/>
      <geometry>
        <mesh filename="meshes/visual/finger.dae"/>
      </geometry>
      <material name="panda_white"/>
    </collision>
    <inertial>
      <mass value="3e-1"/>
      <inertia ixx="1e-3" ixy="0.0" ixz="0.0" iyy="1e-3" iyz="0.0" izz="1e-3"/>
    </inertial>
  </link>
  <joint name="panda_finger_joint1" type="fixed">
    <parent link="panda_hand"/>
    <child link="panda_leftfinger"/>
    <origin rpy="0 0 0" xyz="0 0.03 0.1084"/>
  </joint>
  <joint name="panda_finger_joint2" type="fixed">
    <parent link="panda_hand"/>
    <child link="panda_rightfinger"/>
    <origin rpy="0 0 0" xyz="0 -0.03 0.1084"/>
    <axis xyz="0 -1 0"/>
  </joint>
  <material name="panda_white">
    <color rgba="1. 1. 1. 1."/>
  </material>
</robot>
